Workbook
Name Slicer_Constituency: #N/A
Name Slicer_Party: #N/A
Name Slicer_Result2: #N/A
Name Slicer_State2: #N/A

Sheet GE_2024_Results1
A1: ID | B1: State | C1: Constituency | D1: Candidate | E1: Party | F1: EVM Votes | G1: Postal Votes | H1: Total Votes | I1: % of Votes | J1: Result
A2: 1 | B2: Andaman & Nicobar Islands | C2: Andaman & Nicobar Islands | D2: BISHNU PADA RAY | E2: Bharatiya Janata Party | F2: 102182 | G2: 254 | H2: 102436 | I2: 50.58 | J2: Won
A3: 2 | B3: Andaman & Nicobar Islands | C3: Andaman & Nicobar Islands | D3: KULDEEP RAI SHARMA | E3: Indian National Congress | F3: 77829 | G3: 211 | H3: 78040 | I3: 38.54 | J3: Lost
A4: 3 | B4: Andaman & Nicobar Islands | C4: Andaman & Nicobar Islands | D4: MANOJ PAUL | E4: Andaman Nicobar Democratic Congress | F4: 8236 | G4: 18 | H4: 8254 | I4: 4.08 | J4: Lost
A5: 4 | B5: Andaman & Nicobar Islands | C5: Andaman & Nicobar Islands | D5: D AYYAPPAN | E5: Communist Party of India (Marxist) | F5: 6009 | G5: 8 | H5: 6017 | I5: 2.97 | J5: Lost
A6: 5 | B6: Andaman & Nicobar Islands | C6: Andaman & Nicobar Islands | D6: V.K. ABDUL AZIZ | E6: Independent | F6: 2195 | G6: 8 | H6: 2203 | I6: 1.09 | J6: Lost
A7: 6 | B7: Andaman & Nicobar Islands | C7: Andaman & Nicobar Islands | D7: K J B SELVARAJ | E7: All India Anna Dravida Munnetra Kazhagam | F7: 911 | G7: 3 | H7: 914 | I7: 0.45 | J7: Lost
A8: 7 | B8: Andaman & Nicobar Islands | C8: Andaman & Nicobar Islands | D8: DR ARUN KUMAR MALLIK | E8: Bahujan Samaj Party | F8: 714 | G8: 5 | H8: 719 | I8: 0.36 | J8: Lost
A9: 8 | B9: Andaman & Nicobar Islands | C9: Andaman & Nicobar Islands | D9: RINKU MALA MONDAL | E9: Independent | F9: 539 | G9: 3 | H9: 542 | I9: 0.27 | J9: Lost
A10: 9 | B10: Andaman & Nicobar Islands | C10: Andaman & Nicobar Islands | D10: K VENKAT RAM BABU | E10: Independent | F10: 506 | G10: 1 | H10: 507 | I10: 0.25 | J10: Lost
A11: 10 | B11: Andaman & Nicobar Islands | C11: Andaman & Nicobar Islands | D11: USHA KUMARI | E11: Independent | F11: 378 | G11: 2 | H11: 380 | I11: 0.19 | J11: Lost
A12: 11 | B12: Andaman & Nicobar Islands | C12: Andaman & Nicobar Islands | D12: SALAMAT MONDAL | E12: Socialist Unity Centre Of India (COMMUNIST) | F12: 349 | G12: 2 | H12: 351 | I12: 0.17 | J12: Lost
A13: 12 | B13: Andaman & Nicobar Islands | C13: Andaman & Nicobar Islands | D13: ANAND RAMNATH ARLEKAR | E13: Independent | F13: 342 | G13: - | H13: 342 | I13: 0.17 | J13: Lost
A14: 13 | B14: Andaman & Nicobar Islands | C14: Andaman & Nicobar Islands | D14: NOTA | E14: None of the Above | F14: 1802 | G14: 7 | H14: 1809 | I14: 0.89 | J14: Lost
A15: 14 | B15: Andhra Pradesh | C15: Amalapuram (SC) | D15: G M HARISH (BALAYOGI) | E15: Telugu Desam | F15: 786149 | G15: 10832 | H15: 796981 | I15: 61.25 | J15: Won
A16: 15 | B16: Andhra Pradesh | C16: Amalapuram (SC) | D16: RAPAKA VARAPRASADA RAO | E16: Yuvajana Sramika Rythu Congress Party | F16: 450362 | G16: 4423 | H16: 454785 | I16: 34.95 | J16: Lost
A17: 16 | B17: Andhra Pradesh | C17: Amalapuram (SC) | D17: GOUTHAM JANGA | E17: Indian National Congress | F17: 14523 | G17: 559 | H17: 15082 | I17: 1.16 | J17: Lost
A18: 17 | B18: Andhra Pradesh | C18: Amalapuram (SC) | D18: DORABABU YALLA | E18: Bahujan Samaj Party | F18: 5202 | G18: 186 | H18: 5388 | I18: 0.41 | J18: Lost
A19: 18 | B19: Andhra Pradesh | C19: Amalapuram (SC) | D19: KATRU NAGA BABU | E19: Telugu Nava Garjana Party | F19: 3736 | G19: 5 | H19: 3741 | I19: 0.29 | J19: Lost
A20: 19 | B20: Andhra Pradesh | C20: Amalapuram (SC) | D20: VADDI LALITH KUMAR | E20: Independent | F20: 2974 | G20: 3 | H20: 2977 | I20: 0.23 | J20: Lost
A21: 20 | B21: Andhra Pradesh | C21: Amalapuram (SC) | D21: MAKEY DAVY PRASAD | E21: Independent | F21: 2104 | G21: 7 | H21: 2111 | I21: 0.16 | J21: Lost
A22: 21 | B22: Andhra Pradesh | C22: Amalapuram (SC) | D22: GUDE VENKATESWARULU | E22: Independent | F22: 1741 | G22: 4 | H22: 1745 | I22: 0.13 | J22: Lost
A23: 22 | B23: Andhra Pradesh | C23: Amalapuram (SC) | D23: RAMESH JILLELLA | E23: Jatiya Jana Sena Party | F23: 866 | G23: 6 | H23: 872 | I23: 0.07 | J23: Lost
A24: 23 | B24: Andhra Pradesh | C24: Amalapuram (SC) | D24: YALANGI RAMESH | E24: Jaibhim Rao Bharat Party | F24: 738 | G24: 2 | H24: 740 | I24: 0.06 | J24: Lost
A25: 24 | B25: Andhra Pradesh | C25: Amalapuram (SC) | D25: MATHA KRISHNA | E25: Pyramid Party of India | F25: 718 | G25: 1 | H25: 719 | I25: 0.06 | J25: Lost
... A144: 143 | B144: Andhra Pradesh | C144: Guntur | D144: HARI VENKATA SATISH KURNALA | E144: Jai Bharat National Party | F144: 540 | G144: 2 | H144: 542 | I144: 0.04 | J144: Lost
A145: 144 | B145: Andhra Pradesh | C145: Guntur | D145: VISHNU REDDY LANKIREDDY | E145: Bengaluru Nava Nirmana Party | F145: 461 | G145: - | H145: 461 | I145: 0.03 | J145: Lost
A146: 145 | B146: Andhra Pradesh | C146: Guntur | D146: EMANI. CHANDRASEKHAR RAO | E146: Navodayam Party | F146: 409 | G146: 5 | H146: 414 | I146: 0.03 | J146: Lost
A147: 146 | B147: Andhra Pradesh | C147: Guntur | D147: SHAIK. KHAJAVALI | E147: Independent | F147: 387 | G147: 4 | H147: 391 | I147: 0.03 | J147: Lost
A148: 147 | B148: Andhra Pradesh | C148: Guntur | D148: CHALLAPALLI RATAN RAJU | E148: Viduthalai Chiruthaigal Katchi | F148: 374 | G148: 4 | H148: 378 | I148: 0.03 | J148: Lost
A149: 148 | B149: Andhra Pradesh | C149: Guntur | D149: KANNEBOYINA VAMSI KRISHNA YADAV | E149: Independent | F149: 368 | G149: 7 | H149: 375 | I149: 0.03 | J149: Lost
A150: 149 | B150: Andhra Pradesh | C150: Guntur | D150: MOHAMMAD KHAJA MOINUDDIN CHISTI PASHA | E150: Andhra Pradesh Rashtra Samithi | F150: 353 | G150: 5 | H150: 358 | I150: 0.03 | J150: Lost
A151: 150 | B151: Andhra Pradesh | C151: Guntur | D151: GAYATRI AUDHIPUDI | E151: Independent | F151: 350 | G151: 7 | H151: 357 | I151: 0.03 | J151: Lost
A152: 151 | B152: Andhra Pradesh | C152: Guntur | D152: ASHOK ANAND GALI | E152: Independent | F152: 335 | G152: - | H152: 335 | I152: 0.02 | J152: Lost
A153: 152 | B153: Andhra Pradesh | C153: Guntur | D153: SHAIK ASLAM AKTHER | E153: Independent | F153: 334 | G153: 1 | H153: 335 | I153: 0.02 | J153: Lost
A154: 153 | B154: Andhra Pradesh | C154: Guntur | D154: PATHAN KHAJA (BASHA) | E154: Telugu Rajadhikara Samiti Party | F154: 328 | G154: 4 | H154: 332 | I154: 0.02 | J154: Lost
A155: 154 | B155: Andhra Pradesh | C155: Guntur | D155: AMARTHALURI VENKATESWARA RAO. | E155: Marxist Communist Party of India (United) | F155: 308 | G155: 4 | H155: 312 | I155: 0.02 | J155: Lost
A156: 155 | B156: Andhra Pradesh | C156: Guntur | D156: DR. RAYAPUDI RAJESH VIJAY KUMAR | E156: Indian Labour Party (Ambedkar Phule) | F156: 306 | G156: 4 | H156: 310 | I156: 0.02 | J156: Lost
A157: 156 | B157: Andhra Pradesh | C157: Guntur | D157: BURAGA RATNAM | E157: Loktantrik Janta Dal | F157: 304 | G157: 12 | H157: 316 | I157: 0.02 | J157: Lost
A158: 157 | B158: Andhra Pradesh | C158: Guntur | D158: VANKAYALAPATI VENKATA SIVA RAMANJANEYULU | E158: Independent | F158: 268 | G158: - | H158: 268 | I158: 0.02 | J158: Lost
...

Sheet Won and lost count
R5: ='Won and lost count'!F25 -> 0
E7: Row Labels | F7: Count of Party
E8: Lost | F8: 2
E25: Won Seats | F25: =IFERROR(GETPIVOTDATA("Party",$E$7,"Result","Won"),0) -> 0
E26: Lost Seats | F26: =IFERROR(GETPIVOTDATA("Party",$E$7,"Result","Lost"),0) -> 2

Sheet Total Votes by State
E8: Row Labels | F8: Sum of Total Votes | N8: Row Labels
E9: Telangana | F9: 847 | N9: Goa | O9: =GETPIVOTDATA("Total Votes",'Total Votes by State'!$E$8,"State",N9) -> #REF!
E10: Grand Total | F10: 847 | N10: Andaman & Nicobar Islands | O10: =GETPIVOTDATA("Total Votes",'Total Votes by State'!$E$8,"State",N10) -> #REF!
N11: Andhra Pradesh | O11: =GETPIVOTDATA("Total Votes",'Total Votes by State'!$E$8,"State",N11) -> #REF!
N12: Arunachal Pradesh | O12: =GETPIVOTDATA("Total Votes",'Total Votes by State'!$E$8,"State",N12) -> #REF!
N13: Assam | O13: =GETPIVOTDATA("Total Votes",'Total Votes by State'!$E$8,"State",N13) -> #REF!
N14: Bihar | O14: =GETPIVOTDATA("Total Votes",'Total Votes by State'!$E$8,"State",N14) -> #REF!
N15: Chandigarh | O15: =GETPIVOTDATA("Total Votes",'Total Votes by State'!$E$8,"State",N15) -> #REF!
N16: Chhattisgarh | O16: =GETPIVOTDATA("Total Votes",'Total Votes by State'!$E$8,"State",N16) -> #REF!
N17: Dadra & Nagar Haveli and Daman & Diu | O17: =GETPIVOTDATA("Total Votes",'Total Votes by State'!$E$8,"State",N17) -> #REF!
N18: Gujarat | O18: =GETPIVOTDATA("Total Votes",'Total Votes by State'!$E$8,"State",N18) -> #REF!
N19: Haryana | O19: =GETPIVOTDATA("Total Votes",'Total Votes by State'!$E$8,"State",N19) -> #REF!
N20: Himachal Pradesh | O20: =GETPIVOTDATA("Total Votes",'Total Votes by State'!$E$8,"State",N20) -> #REF!
N21: Jammu and Kashmir | O21: =GETPIVOTDATA("Total Votes",'Total Votes by State'!$E$8,"State",N21) -> #REF!
N22: Jharkhand | O22: =GETPIVOTDATA("Total Votes",'Total Votes by State'!$E$8,"State",N22) -> #REF!
... N44: West Bengal | O44: =GETPIVOTDATA("Total Votes",'Total Votes by State'!$E$8,"State",N44) -> #REF!

Sheet % Vote Share by Party
D7: Row Labels | E7: Sum of Total Votes
D8: Indian National Yuva Jana Party | E8: 1
D9: Grand Total | E9: 1

Sheet Seats Won by Party
D4: Total Seats | E4: =GETPIVOTDATA("Result",$D$9) -> 2
D9: Row Labels | E9: Count of Result
D10: Indian National Yuva Jana Party | E10: 2
D11: Grand Total | E11: 2
L23: ='Seats Won by Party'!E4 -> 2
L24: ='Seats Won by Party'!E4 -> 2

Sheet Dashboard 

Sheet Seats won Count by State
D7: Row Labels | E7: Count of Result
D8: Telangana | E8: 2
D9: Grand Total | E9: 2

Sheet Votes Comparison (EVM vs Postal
D9: Row Labels | E9: Sum of EVM Votes | F9: Sum of Postal Votes
D10: KRANTHI KUMAR BANDELA | E10: 844 | F10: 3
D11: Grand Total | E11: 844 | F11: 3
